Workbook

Sheet 发票箱单
A1: 客户原单号：（必填） | C1: FBA号：（填写FBA主单号 12位） | E1: 务必填写规范：(只做内容填充，不允许调整格式，不允许合并单元格，填写内容不允许有空格。)
A2: 交货仓库：（必填） | C2: 是否购买保险 （选填）： | E2: 注意：表格中蓝色内容为必填项，黄色内容为选填项 备注：1，成套的产品需注明单套包含的件数以及品名； 2，垫子类、纸盒支架类需提供规格（如尺寸和高度），请填写到C12栏备注下 3，图片请提供高清的（再缩放到单元格）； 4、申报币种必须匹配：英国空运/海运/铁路（英镑），德国（欧元），美国（美金）--也可参考表格2 5、一箱货有多个产品，箱号重复填写即可 6、备注栏：C12栏备注下单特殊需求，例如备注和哪票货合并清关；U17栏备注产品信息，例如部分产品单独报关 | G2: 填写范本 请参考
A3: 交货客户代号：（必填） | C3: 清关方式（必填）： | D3: =IF(OR(ISNUMBER(FIND("PVA",$B$4)),ISNUMBER(FIND("递延",$B$4)),ISNUMBER(FIND("VAT",$B$4)),ISNUMBER(FIND("不包税",$B$4)),ISNUMBER(FIND("不含税",$B$4)),ISNUMBER(FIND("VAT",$B$4))),"单票清关","包税") -> 包税
A4: 走货线路：（必填） | C4: 发件人公司：
A5: 报关方式：（必填） | C5: 发件人地址：
A6: 目的地/国家：（必填）（中文） | C6: VAT和EORI注册公司名：
A7: 地址类型*（必填） | C7: VAT和EORI注册地址：
A8: 收货地址名称/亚马逊仓库代码* | C8: VAT增值税号*
A9: 收件公司（必填）： | C9: EORI号*
A10: 收件人（必填） ：
A11: 联系电话 （选填）：
A12: 收件邮编：（必填） | C12: 备注 | E12: 可以备注预计几号送仓或交惠州仓，厦门仓等；如有合并清关或者合并报关，需要明确哪几票合并
A13: 省份/州（选填）： | C13: 邮箱 | D13: 必填 | E13: 请看批注！部分走货渠道必填！
A14: 城市（必填）：
A15: 收件地址：（必填）
A16: 总件数（必填） | B16: 1 | S16: 不得删除！ | T16: 不得删除！
A17: 亚马逊FBA子单号/箱唛号（必填）（FBA号正确19位） 非亚马逊箱号就填写1 2 3 等数字 单一品名的比如有10箱就填写1~10（注意使用符号~） 混装的产品要分行写（箱号相同代表是同一箱货） 如下面的T-恤 和运动鞋申报 | B17: Reference ID（亚马逊追踪编码） 不是亚马逊的就空着不填 | C17: 中文品名（必填） 根据实际品名填写 | D17: 英文品名（必填） 根据实际英文品名填写 | E17: 材质（中英文填写）（必填） 根据实际填写 | F17: 用途（中英文填写）（必填） 根据实际填写 | G17: 国外海关编码（必填） 根据实际填写 | H17: 产品类型/属性 带电/磁/液体/普货 根据实际情况填写 | I17: 单箱产品数量PCS（必填） 根据单箱实际填写 | J17: 箱数/件数CTN（必填）表达一行的总箱数 | K17: 申报单价币种 欧洲固定EUR 英国固定GBP 其他国家固定USD | L17: 单个产品申报单价 | M17: 单个产品净重KG(必填) 一定要填数字 不能是文本 | N17: 产品高清图片 （必须缩在方框内） | O17: 品牌 （如实申报） | P17: 品牌类型 （如实申报） | Q17: 型号 （如实申报） | R17: 销售链接 （填写链接的前后不能有空格） | S17: 备注（产品的其他特殊说明） | T17: 产品单位 （个/包/条等） | U17: 实重 | V17: 长 | W17: 宽 | X17: 高
K18: =VLOOKUP($B$6,'走货线路名和申报币别要求-不能删'!E:F,2,0) -> #N/A
K19: =VLOOKUP($B$6,'走货线路名和申报币别要求-不能删'!E:F,2,0) -> #N/A
K20: =VLOOKUP($B$6,'走货线路名和申报币别要求-不能删'!E:F,2,0) -> #N/A
K21: =VLOOKUP($B$6,'走货线路名和申报币别要求-不能删'!E:F,2,0) -> #N/A
K22: =VLOOKUP($B$6,'走货线路名和申报币别要求-不能删'!E:F,2,0) -> #N/A
K23: =VLOOKUP($B$6,'走货线路名和申报币别要求-不能删'!E:F,2,0) -> #N/A
K24: =VLOOKUP($B$6,'走货线路名和申报币别要求-不能删'!E:F,2,0) -> #N/A
K25: =VLOOKUP($B$6,'走货线路名和申报币别要求-不能删'!E:F,2,0) -> #N/A
K26: =VLOOKUP($B$6,'走货线路名和申报币别要求-不能删'!E:F,2,0) -> #N/A
K27: =VLOOKUP($B$6,'走货线路名和申报币别要求-不能删'!E:F,2,0) -> #N/A
K28: =VLOOKUP($B$6,'走货线路名和申报币别要求-不能删'!E:F,2,0) -> #N/A
K29: =VLOOKUP($B$6,'走货线路名和申报币别要求-不能删'!E:F,2,0) -> #N/A
... K45: =VLOOKUP($B$6,'走货线路名和申报币别要求-不能删'!E:F,2,0) -> #N/A

Sheet 走货线路名和申报币别要求-不能删
A1: 走货渠道 | B1: 申报币种 | C1: 备注 | E1: 国家 | F1: 币种 | H1: 报关方式 | L1: 走货渠道 | M1: 国家 | O1: 欧洲国家
A2: 中欧铁路UPS限时达 | B2: EUR | C2: 含税 | E2: 德国 | F2: EUR | H2: 单独报关 | L2: 中欧铁路UPS限时达 | M2: 欧洲
A3: 海运法国专线DPD包税 | B3: EUR | C3: 含税 | E3: 荷兰 | F3: EUR | H3: 合并单独报关 | L3: 海运法国专线DPD包税 | M3: 欧洲
A4: 海运法国专线DPD不包税 | B4: EUR | C4: VAT增值税递延 | E4: 捷克 | F4: EUR | H4: 不报关 | L4: 海运法国专线DPD不包税 | M4: 欧洲
A5: 中欧铁路UPS | B5: 欧元 | C5: 含税 | E5: 波兰 | F5: EUR | H5: 9810报关 | L5: 中欧铁路UPS | M5: 欧洲
A6: 中欧铁路不包税UPS-PVA | C6: VAT增值税递延 | E6: 卢森堡 | F6: EUR | H6: 9710报关 | L6: 中欧铁路不包税UPS-PVA | M6: 欧洲
A7: 中欧德国专线海运按公斤-含税 | C7: 含税 | E7: 比利时 | F7: EUR | H7: 一达通单独报关 | L7: 中欧德国专线海运按公斤-含税 | M7: 欧洲 | O7: 奥地利
A8: 中欧德国专线海运按公斤-不含税 | C8: VAT增值税递延 | E8: 法国 | F8: EUR | H8: 一达通9810报关 | L8: 中欧德国专线海运按公斤-不含税 | M8: 欧洲 | O8: 比利时
A9: 中欧铁路超大件TNT专线 | C9: 含税 | E9: 西班牙 | F9: EUR | H9: 一达通9710报关 | L9: 中欧铁路超大件TNT专线 | M9: 欧洲 | O9: 保加利亚
A10: 德国海运卡派包税 | C10: 含税 | E10: 意大利 | F10: EUR | L10: 德国海运卡派包税 | M10: =LEFT(L10,2) -> 德国 | O10: 克罗地亚
A11: 德国海运卡派-PVA | C11: VAT增值税递延 | E11: 葡萄牙 | F11: EUR | L11: 德国海运卡派-PVA | M11: =LEFT(L11,2) -> 德国 | O11: 捷克
A12: 德国海运卡派包税-按KG | C12: 含税 | E12: 瑞典 | F12: EUR | L12: 德国海运卡派包税-按KG | M12: =LEFT(L12,2) -> 德国 | O12: 丹麦
A13: 中欧海运快船比利时清包税DPD | C13: 含税 | E13: 爱沙尼亚 | F13: EUR | L13: 中欧海运快船比利时清包税DPD | M13: 欧洲 | O13: 爱沙尼亚
A14: 中欧海运亚马逊特惠 | C14: 含税 | E14: 立陶宛 | F14: EUR | L14: 中欧海运亚马逊特惠 | M14: 欧洲 | O14: 芬兰
A15: 中欧海运亚马逊特惠不包税 | C15: VAT增值税预付 | E15: 奥地利 | F15: EUR | L15: 中欧海运亚马逊特惠不包税 | M15: 欧洲 | O15: 法国
A16: 欧洲海运电动车渠道 | C16: 含税 | E16: 丹麦 | F16: EUR | L16: 欧洲海运电动车渠道 | M16: =LEFT(L16,2) -> 欧洲 | O16: 德国
A17: 欧洲海运普货超大件DHL渠道 | C17: 含税 | E17: 克罗地亚 | F17: EUR | L17: 欧洲海运普货超大件DHL渠道 | M17: =LEFT(L17,2) -> 欧洲 | O17: 希腊
A18: 中欧海运超大件TNT | C18: 含税 | E18: 斯洛伐克 | F18: EUR | L18: 中欧海运超大件TNT | M18: 欧洲 | O18: 匈牙利
A19: 中欧海运快船比利时清不含税PVA | C19: VAT增值税预付 | E19: 匈牙利 | F19: EUR | L19: 中欧海运快船比利时清不含税PVA | M19: 欧洲 | O19: 冰岛
A20: 中欧德国专线海运按方-含税 | C20: 含税 | E20: 罗马尼亚 | F20: EUR | L20: 中欧德国专线海运按方-含税 | M20: 欧洲 | O20: 爱尔兰
A21: 中欧德国专线海运按方-不含税 | C21: VAT增值税预付 | E21: 保加利亚 | F21: EUR | L21: 中欧德国专线海运按方-不含税 | M21: 欧洲 | O21: 意大利
A22: 中欧海运快船希腊比雷清DPD | E22: 爱尔兰 | F22: EUR | L22: 中欧海运快船希腊比雷清DPD | M22: 欧洲 | O22: 拉脱维亚
A23: 中欧大陆空派 | C23: 含税 | E23: 芬兰 | F23: EUR | L23: 中欧大陆空派 | M23: 欧洲 | O23: 立陶宛
A24: 中欧香港空派 | C24: 含税 | E24: 希腊 | F24: EUR | L24: 中欧香港空派 | M24: 欧洲 | O24: 卢森堡
A25: 中欧空派不包税 | C25: VAT增值税预付 | E25: 斯洛文尼亚 | F25: EUR | L25: 中欧空派不包税 | M25: 欧洲 | O25: 摩纳哥
A26: 欧洲空派TNT/卡车超大件不包税 | C26: VAT增值税预付 | E26: 拉脱维亚 | F26: EUR | L26: 欧洲空派TNT/卡车超大件不包税 | M26: =LEFT(L26,2) -> 欧洲 | O26: 荷兰
A27: 欧洲空派TNT/卡车超大件 | C27: 含税 | E27: 英国 | F27: GBP | L27: 欧洲空派TNT/卡车超大件 | M27: =LEFT(L27,2) -> 欧洲 | O27: 挪威
A28: 欧洲海运普货超大件DHL渠道-不包税 | C28: VAT增值税预付 | E28: 美国 | F28: USD | L28: 欧洲海运普货超大件DHL渠道-不包税 | M28: =LEFT(L28,2) -> 欧洲 | O28: 波兰
A29: 中欧卡车PVA-UPS | C29: VAT增值税递延 | E29: 加拿大 | F29: USD | L29: 中欧卡车PVA-UPS | M29: 欧洲 | O29: 葡萄牙
A30: 中欧铁路整柜 | C30: 含税 | E30: 澳洲 | F30: USD | L30: 中欧铁路整柜 | M30: 欧洲 | O30: 罗马尼亚
A31: 中欧铁路整柜不包税 | C31: VAT增值税递延 | E31: 墨西哥 | F31: USD | L31: 中欧铁路整柜不包税 | M31: 欧洲 | O31: 斯洛伐克
A32: 中欧海运整柜 | C32: 含税 | E32: 日本 | F32: USD | L32: 中欧海运整柜 | M32: 欧洲 | O32: 斯洛文尼亚
A33: 中欧铁路亚马逊特惠 | C33: 含税 | E33: 菲律宾 | F33: USD | L33: 中欧铁路亚马逊特惠 | M33: 欧洲 | O33: 西班牙
A34: 中欧铁路亚马逊特惠不包税 | C34: VAT增值税递延 | E34: 台湾 | F34: USD | L34: 中欧铁路亚马逊特惠不包税 | M34: 欧洲 | O34: 瑞典
A35: 德国海外仓暂存 | C35: 含税 | E35: 泰国 | F35: USD | L35: 德国海外仓暂存 | M35: =LEFT(L35,2) -> 德国
A36: 电池专线DHL渠道 | C36: 含税 | E36: 伊朗 | F36: USD | L36: 电池专线DHL渠道 | M36: 欧洲
A37: 英国海外仓暂存 | B37: 英镑 | C37: 含税 | E37: 越南 | F37: USD | L37: 英国海外仓暂存 | M37: =LEFT(L37,2) -> 英国
A38: 英国海外仓暂存-PVA递延 | C38: VAT增值税预付 | E38: 新加坡 | F38: USD | L38: 英国海外仓暂存-PVA递延 | M38: =LEFT(L38,2) -> 英国
A39: 英国铁路包税 | C39: 含税 | L39: 英国铁路包税 | M39: =LEFT(L39,2) -> 英国
A40: 英国铁路-不包税 | C40: VAT增值税预付 | L40: 英国铁路-不包税 | M40: =LEFT(L40,2) -> 英国
...

Sheet 填写范本
